Workbook

Sheet 1. Assumptions
A1: SMART-RECOVERY INITIATIVE — ROI MODEL
A2: Tab 1: Assumptions Register
A3: Blue text = hardcoded input | Black text = formula | Yellow bg = key assumption requiring attention
A5: Assumption | B5: Value | C5: Unit | D5: Source | E5: Confidence | F5: Notes
A6: A. OPERATIONAL COST BENCHMARKS
A7: Blended agent cost per hour | B7: 22 | C7: £/hr | D7: finance_assumptions_sample.csv | E7: High | F7: GBP22.00/hr confirmed by finance. Use for all agent time calculations.
A8: Blended agent cost per minute | B8: =B7/60 -> 0.36666667 | C8: £/min | D8: Derived from B7 | E8: High | F8: Calculated — do not edit directly.
A9: Working days per month | B9: 21 | C9: days | D9: finance_assumptions_sample.csv | E9: High | F9: Standard working month assumption from finance.
A10: Working hours per day | B10: 7.5 | C10: hrs | D10: Operational standard | E10: High | F10: Standard working day for collections agents.
A11: Total agent working hours per month | B11: =B9*B10 -> 157.5 | C11: hrs | D11: Derived | E11: High | F11: 21 days x 7.5 hrs = 157.5 hrs/agent/month.
A12: Number of active agents | B12: 58 | C12: agents | D12: recovery_activity_tracker_sample.csv | E12: High | F12: 58 unique agents confirmed in activity tracker sample.
A13: Total agent workforce hours per month | B13: =B11*B12 -> 9135 | C13: hrs | D13: Derived | E13: High | F13: Total hours across all 58 agents.
A14: Current average handling time (all activities) | B14: 7 | C14: mins | D14: recovery_activity_tracker_sample.csv | E14: High | F14: 7.00 min average handling time confirmed from 9,890 logged activities.
A15: Current average handling time (complex/manual cases) | B15: 18 | C15: mins | D15: finance_assumptions_sample.csv | E15: High | F15: 18 min current handling time for manual cases per finance assumptions.
A16: Target handling time (self-service eligible cases) | B16: 10 | C16: mins | D16: finance_assumptions_sample.csv | E16: Medium | F16: Finance target of 10 min for straightforward self-service cases.
A17: Handling time saving per self-served case | B17: =B15-B16 -> 8 | C17: mins | D17: Derived | E17: High | F17: 8 min saving per case if moved to self-service.
A18: Cost saving per self-served case | B18: =B17*B8 -> 2.9333333 | C18: £/case | D18: Derived | E18: High | F18: 8 min x GBP0.37/min = GBP2.93 per case. Matches finance assumptions.
A20: B. PORTFOLIO & BASELINE METRICS
A21: Total delinquent account portfolio | B21: 100000 | C21: accounts | D21: Case study briefing | E21: High | F21: 100,000+ delinquent accounts stated in project briefing.
A22: Sample portfolio size (dataset) | B22: 3246 | C22: accounts | D22: delinquent_accounts_sample.csv | E22: High | F22: 3,246 accounts in the sample dataset used for analysis.
A23: Self-service technically eligible (sample rate) | B23: 0.775 | C23: rate | D23: delinquent_accounts_sample.csv | E23: High | F23: 77.5% flagged eligible by risk_flag=N and delinquency stage. Rules-based.
A24: Finance conservative self-service assumption | B24: 0.38 | C24: rate | D24: finance_assumptions_sample.csv | E24: Medium | F24: 38% working estimate from finance — layers in dropout, channel preference, complexity buffer.
A25: Predicted adoption rate (of technically eligible) | B25: 0.65 | C25: rate | D25: Daniel Okoye — layered model | E25: Low | F25: Estimated adoption of eligible accounts. Requires post-launch validation. Daniel Q1.
A26: Effective self-service population (portfolio) | B26: =B21*B23*B24*B25 -> 19142.5 | C26: accounts | D26: Derived — 3-layer model | E26: Low | F26: Technical eligibility x finance conservative x adoption. Daniel's layered funnel.
A27: Monthly recovery baseline | B27: 8000000 | C27: £/month | D27: finance_assumptions_sample.csv | E27: High | F27: GBP8,000,000 monthly recovery baseline confirmed by finance assumptions.
A28: Annualised recovery baseline | B28: =B27*12 -> 96000000 | C28: £/year | D28: Derived | E28: High | F28: GBP8M x 12 = GBP96M annual portfolio.
A29: Missed follow-up rate | B29: 0.14 | C29: rate | D29: finance_assumptions_sample.csv | E29: Medium | F29: 14% of collection files suffer missed or delayed touchpoints. Finance estimate.
A30: Monthly revenue at risk from missed follow-ups | B30: =B27*B29 -> 1120000 | C30: £/month | D30: Derived | E30: Medium | F30: 14% of GBP8M = GBP1.12M/month leaking from portfolio.
A31: Annual revenue at risk from missed follow-ups | B31: =B30*12 -> 13440000 | C31: £/year | D31: Derived | E31: Medium | F31: GBP1.12M x 12 = GBP13.44M annualised leakage.
A33: C. REVENUE UPLIFT ASSUMPTIONS — LOW CONFIDENCE: SENSITIVITY TESTING MANDATORY
A34: Plan selection uplift — base assumption | B34: 0.04 | C34: % | D34: finance_assumptions_sample.csv | E34: Low | F34: Finance rated LOW confidence. Drives GBP320k/month at base. Must be sensitivity tested.
A35: Plan selection uplift — conservative scenario | B35: 0.02 | C35: % | D35: Sensitivity assumption | E35: Low | F35: 50% haircut on base assumption for conservative scenario.
A36: Plan selection uplift — floor scenario | B36: 0.01 | C36: % | D36: Sensitivity assumption | E36: Low | F36: 75% haircut on base assumption for floor/stress scenario.
A37: Promise capture uplift — base assumption | B37: 0.025 | C37: % | D37: finance_assumptions_sample.csv | E37: Low | F37: Finance rated LOW confidence. Drives GBP200k/month at base. Must be sensitivity tested.
A38: Promise capture uplift — conservative scenario | B38: 0.0125 | C38: % | D38: Sensitivity assumption | E38: Low | F38: 50% haircut on base assumption for conservative scenario.
A39: Promise capture uplift — floor scenario | B39: 0.005 | C39: % | D39: Sensitivity assumption | E39: Low | F39: 80% haircut on base assumption for floor/stress scenario.
A40: Monthly revenue uplift — plan selection (base) | B40: =B27*B34 -> 320000 | C40: £/month | D40: Derived | E40: Low | F40: GBP8M x 4% = GBP320,000/month at base.
A41: Monthly revenue uplift — promise capture (base) | B41: =B27*B37 -> 200000 | C41: £/month | D41: Derived | E41: Low | F41: GBP8M x 2.5% = GBP200,000/month at base.
A42: Annual revenue uplift — combined (base) | B42: =(B40+B41)*12 -> 6240000 | C42: £/year | D42: Derived | E42: Low | F42: GBP520k/month x 12 = GBP6.24M/year at base. LOW CONFIDENCE.
A44: D. IMPLEMENTATION COST ASSUMPTIONS
...

Sheet 2. Baseline Metrics
A1: SMART-RECOVERY INITIATIVE — BASELINE METRICS
A2: Tab 2: Current-State Operational Baseline
A3: All figures drawn from confirmed datasets. Directional estimates noted explicitly.
A5: Metric | B5: Value | C5: Unit | D5: Source / Note | E5: Confidence
A6: PORTFOLIO SCALE
A7: Total delinquent accounts (portfolio) | B7: ='1. Assumptions'!B21 -> 100000 | C7: accounts | D7: Case study briefing — portfolio total | E7: High
A8: Total delinquent accounts (sample) | B8: ='1. Assumptions'!B22 -> 3246 | C8: accounts | D8: delinquent_accounts_sample.csv | E8: High
A9: Total outstanding portfolio balance | B9: 26559357 | C9: £ | D9: delinquent_accounts_sample.csv — sample figure | E9: Medium
A10: Total overdue amount (sample) | B10: 3052004 | C10: £ | D10: delinquent_accounts_sample.csv | E10: High
A11: Average days past due | B11: 37 | C11: days | D11: delinquent_accounts_sample.csv | E11: High
A12: Average outstanding balance per account | B12: 8177 | C12: £ | D12: delinquent_accounts_sample.csv | E12: High
A13: SELF-SERVICE ELIGIBILITY
A14: Self-service eligible accounts (sample rate) | B14: ='1. Assumptions'!B23 -> 0.775 | C14: % | D14: delinquent_accounts_sample.csv — rules-based flag | E14: High
A15: Self-service eligible accounts (portfolio estimate) | B15: =B7*B14 -> 77500 | C15: accounts | D15: Derived — apply sample rate to portfolio | E15: Medium
A16: Finance conservative self-service estimate | B16: ='1. Assumptions'!B24 -> 0.38 | C16: % | D16: finance_assumptions_sample.csv — includes dropout buffer | E16: Medium
A17: Gap — technical eligibility vs finance estimate | B17: =B14-B16 -> 0.395 | C17: pp | D17: 38% vs 77.5% — Daniel Q1 explains 3-layer haircut | E17: High
A18: Effective portal addressable population | B18: ='1. Assumptions'!B26 -> 19142.5 | C18: accounts | D18: 3-layer model: eligibility x conservative x adoption | E18: Low
A19: OPERATIONAL WASTE — ACTIVITY TRACKER
A20: Total activities logged (sample) | B20: 9890 | C20: activities | D20: recovery_activity_tracker_sample.csv | E20: High
A21: Total manual effort (sample) | B21: 1153.8 | C21: hours | D21: recovery_activity_tracker_sample.csv | E21: High
A22: Average handling time per activity | B22: ='1. Assumptions'!B14 -> 7 | C22: mins | D22: recovery_activity_tracker_sample.csv | E22: High
A23: Duplicate activities (count) | B23: 2020 | C23: activities | D23: recovery_activity_tracker_sample.csv | E23: High
A24: Duplicate activities (rate) | B24: 0.204 | C24: % | D24: recovery_activity_tracker_sample.csv — 20.4% of all activities | E24: High
A25: Hours wasted on duplicate activities | B25: 230.1 | C25: hours | D25: recovery_activity_tracker_sample.csv — directional sample figure | E25: High
A26: Cost of duplicate activities | B26: =B25*'1. Assumptions'!B7 -> 5062.2 | C26: £ | D26: Derived: 230.1 hrs x GBP22/hr — sample period only | E26: High
A27: Back-office admin burden (rate) | B27: 0.342 | C27: % | D27: recovery_activity_tracker_sample.csv — 34.2% of hours | E27: High
A28: Back-office admin hours (sample) | B28: 394.6 | C28: hours | D28: recovery_activity_tracker_sample.csv | E28: High
A29: Cost of back-office admin burden | B29: =B28*'1. Assumptions'!B7 -> 8681.2 | C29: £ | D29: Derived: 394.6 hrs x GBP22/hr — sample period only | E29: High
A30: Spreadsheet reconcile duplicate rate | B30: 0.723 | C30: % | D30: recovery_activity_tracker_sample.csv — 72.3% of 1,458 activities | E30: High
A31: Status check duplicate rate | B31: 0.69 | C31: % | D31: recovery_activity_tracker_sample.csv — 69.0% of 1,400 activities | E31: High
A32: Activities with no follow-up date | B32: 1465 | C32: activities | D32: recovery_activity_tracker_sample.csv — 14.8% at risk of funnel dropout | E32: High
A33: Accounts stuck in Awaiting Follow-Up | B33: 643 | C33: accounts | D33: delinquent_accounts_sample.csv — largest single status backlog | E33: High
A34: Accounts with no status (unassigned) | B34: 69 | C34: accounts | D34: delinquent_accounts_sample.csv — compliance gap | E34: High
A35: FINANCIAL BASELINE
A36: Monthly recovery baseline | B36: ='1. Assumptions'!B27 -> 8000000 | C36: £/month | D36: finance_assumptions_sample.csv | E36: High
A37: Annual recovery baseline | B37: ='1. Assumptions'!B28 -> 96000000 | C37: £/year | D37: Derived | E37: High
A38: Missed follow-up rate | B38: ='1. Assumptions'!B29 -> 0.14 | C38: % | D38: finance_assumptions_sample.csv | E38: Medium
A39: Monthly revenue at risk from missed follow-ups | B39: ='1. Assumptions'!B30 -> 1120000 | C39: £/month | D39: Derived: 14% x GBP8M | E39: Medium
A40: Annual revenue at risk | B40: ='1. Assumptions'!B31 -> 13440000 | C40: £/year | D40: Derived | E40: Medium
A41: GBP500k operational loss estimate (Amina's team) | B41: 500000 | C41: £/year | D41: Operational estimate — Amina Rahman. NOT finance-recognised. Caveat. | E41: Low
...

Sheet 3. Opportunities
A1: SMART-RECOVERY INITIATIVE — OPPORTUNITY REGISTER
A2: Tab 3: Automation Opportunity Comparison (6 Options)
A3: All cost/benefit figures are estimates. Revenue uplift is LOW CONFIDENCE until portal performance data exists. Hard savings are HIGH CONFIDENCE.
A5: # | B5: Opportunity | C5: Pain Points / JTBD | D5: Implementation Cost | E5: Annual Hard Saving | F5: Annual Revenue Uplift | G5: Annual Total Benefit | H5: Net Year 1 Benefit | I5: Softer Benefits | J5: Phase
A6: AO-01 | B6: Promise-to-Pay Self-Service Capture | C6: PP-04, PP-02 JTBD-01, JTBD-04 | D6: 45000 | E6: ='1. Assumptions'!B26*('1. Assumptions'!B17/60)*'1. Assumptions'!B7*12 -> 673816 | F6: ='1. Assumptions'!B27*'1. Assumptions'!B36*12 -> 960000 | G6: =E6+F6 -> 1633816 | H6: =G6-D6 -> 1588816 | I6: Reduces inbound call volume. Frees agent time for complex cases. Proven 89.9% modelled conversion. | J6: Phase 1
A7: AO-02 | B7: Automated Callback Triggering | C7: PP-02, PP-04 JTBD-04, JTBD-03 | D7: 45000 | E7: ='2. Baseline Metrics'!B25*'1. Assumptions'!B7*12 -> 60746.4 | F7: ='1. Assumptions'!B27*'1. Assumptions'!B29*0.3*12 -> 4032000 | G7: =E7+F7 -> 4092746.4 | H7: =G7-D7 -> 4047746.4 | I7: Eliminates 643-account backlog. Reduces 14% missed follow-up rate. No integration required. | J7: Phase 1
A8: AO-03 | B8: Real-Time Status Synchronisation | C8: PP-01, PP-03, PP-05 JTBD-05 | D8: 85000 | E8: ='2. Baseline Metrics'!B28*'1. Assumptions'!B7*12*0.7 -> 72922.08 | F8: ='1. Assumptions'!B27*'1. Assumptions'!B29*0.1*12 -> 1344000 | G8: =E8+F8 -> 1416922.1 | H8: =G8-D8 -> 1331922.1 | I8: Eliminates 200-tab spreadsheet. Reduces 72.3% reconcile duplicate rate. Enables all other AOs. | J8: Pre-Phase 1
A9: AO-04 | B9: Customer Balance & Account Summary View | C9: PP-09, PP-08 JTBD-01 | D9: 45000 | E9: ='1. Assumptions'!B26*2*('1. Assumptions'!B14/60)*'1. Assumptions'!B7*12 -> 1179178 | F9: ='1. Assumptions'!B27*'1. Assumptions'!B34*0.5*12 -> 1920000 | G9: =E9+F9 -> 3099178 | H9: =G9-D9 -> 3054178 | I9: Reduces 3-call average per customer. Increases customer willingness to engage. Portal foundation. | J9: Phase 1
A10: AO-05 | B10: Risk-Based Queue Prioritisation | C10: PP-08, PP-02 JTBD-03 | D10: 85000 | E10: ='1. Assumptions'!B13*'1. Assumptions'!B7*0.05*12 -> 120582 | F10: ='1. Assumptions'!B27*0.01*12 -> 960000 | G10: =E10+F10 -> 1080582 | H10: =G10-D10 -> 995582 | I10: High-value accounts contacted first. Measurable improvement in recovery velocity. | J10: Phase 2
A11: AO-06 | B11: Automated Follow-Up Reminder Notifications | C11: PP-02, PP-04 JTBD-01, JTBD-04 | D11: 45000 | E11: =306*('1. Assumptions'!B26/'2. Baseline Metrics'!B8)*'1. Assumptions'!B7*12 -> 476404.1 | F11: ='1. Assumptions'!B27*'1. Assumptions'!B29*0.2*12 -> 2688000 | G11: =E11+F11 -> 3164404.1 | H11: =G11-D11 -> 3119404.1 | I11: Reduces promise dropout. Compliance sign-off required. Low build cost. | J11: Phase 1b

Sheet 4. Calculations
A1: SMART-RECOVERY INITIATIVE — SENSITIVITY ANALYSIS
A2: Tab 4: Calculations & Scenario Testing
A3: Daniel Okoye confirmed: sensitivity matrix is non-negotiable. Both uplift assumptions rated LOW confidence. Hard savings presented separately.
A5: A. CONFIRMED HARD SAVINGS — HIGH CONFIDENCE (Defensible with operational data)
A6: Saving Category | B6: Calculation Basis | C6: Annual Value (£) | D6: Confidence | E6: Source | F6: Notes
A7: Duplicate activity elimination | B7: 230.1 hrs x GBP22/hr x 12 periods | C7: ='1. Assumptions'!B7*230.1*12 -> 60746.4 | D7: High | E7: activity_tracker_sample.csv | F7: Sample-period figure — directional. Annualised using 12 periods.
A8: Back-office admin burden reduction (50% target) | B8: 394.6 hrs x GBP22/hr x 12 x 50% reduction | C8: ='1. Assumptions'!B7*394.6*12*0.5 -> 52087.2 | D8: High | E8: activity_tracker_sample.csv | F8: Conservative 50% reduction target. Full elimination not assumed in Year 1.
A9: Handling time saving per self-served case (AO-01/04) | B9: 8 min x GBP0.37/min x effective portal population x 12 | C9: ='1. Assumptions'!B26*('1. Assumptions'!B17/60)*'1. Assumptions'!B7 -> 56151.333 | D9: Medium | E9: finance_assumptions_sample.csv | F9: Depends on portal adoption — rated Medium as population estimate is Low confidence.
A10: Total confirmed hard savings (annual) | B10: Sum of above | C10: =C7+C8+C9 -> 168984.93 | D10: Medium | E10: Derived | F10: Blended confidence — C9 pulls from Low-confidence population figure.
A12: B. REVENUE UPLIFT SENSITIVITY MATRIX — LOW CONFIDENCE: Three scenarios required
A13: Scenario | B13: Plan Selection Uplift | C13: Promise Capture Uplift | D13: Combined Monthly Uplift | E13: Combined Annual Uplift | F13: Net Benefit (after GBP85k mid cost)
A14: Base (finance assumption) | B14: ='1. Assumptions'!B34 -> 0.04 | C14: ='1. Assumptions'!B37 -> 0.025 | D14: ='1. Assumptions'!B27*(B14+C14) -> 520000 | E14: =D14*12 -> 6240000 | F14: =E14-'1. Assumptions'!B46 -> 6155000
A15: Conservative (50% haircut) | B15: ='1. Assumptions'!B35 -> 0.02 | C15: ='1. Assumptions'!B38 -> 0.0125 | D15: ='1. Assumptions'!B27*(B15+C15) -> 260000 | E15: =D15*12 -> 3120000 | F15: =E15-'1. Assumptions'!B46 -> 3035000
A16: Floor / Stress (75-80% haircut) | B16: ='1. Assumptions'!B36 -> 0.01 | C16: ='1. Assumptions'!B39 -> 0.005 | D16: ='1. Assumptions'!B27*(B16+C16) -> 120000 | E16: =D16*12 -> 1440000 | F16: =E16-'1. Assumptions'!B46 -> 1355000
A19: C. COMBINED BUSINESS CASE — Hard Savings + Revenue Uplift
A20: Component | B20: Base Scenario | C20: Conservative Scenario | D20: Floor Scenario | E20: Confidence
A21: Confirmed hard savings (annual) | B21: =C10 -> 168984.93 | C21: =C10 -> 168984.93 | D21: =C10 -> 168984.93 | E21: Medium
A22: Revenue uplift (annual) | B22: =E14 -> 6240000 | C22: =E15 -> 3120000 | D22: =E16 -> 1440000 | E22: Low | F22: LOW CONFIDENCE — do not blend with hard savings
A23: Total annual benefit | B23: =B21+B22 -> 6408984.9 | C23: =C21+C22 -> 3288984.9 | D23: =D21+D22 -> 1608984.9 | E23: Low
A24: Implementation cost (mid-complexity) | B24: =-'1. Assumptions'!B46 -> -85000 | C24: =-'1. Assumptions'!B46 -> -85000 | D24: =-'1. Assumptions'!B46 -> -85000 | E24: Medium
A25: Net Year 1 benefit | B25: =B23+B24 -> 6323984.9 | C25: =C23+C24 -> 3203984.9 | D25: =D23+D24 -> 1523984.9 | E25: Low | F25: Positive in all three scenarios
A26: Simple payback period (months) | B26: =ABS(B24/(B23/12)) -> 0.15915157 | C26: =ABS(C24/(C23/12)) -> 0.31012608 | D26: =ABS(D24/(D23/12)) -> 0.63394006 | E26: Low
A27: 12-month ROI | B27: =B25/ABS(B24) -> 74.399823 | C27: =C25/ABS(C24) -> 37.69394 | D27: =D25/ABS(D24) -> 17.929235 | E27: Low

Sheet 5. ROI Summary
A1: SMART-RECOVERY INITIATIVE — ROI & RANKING SUMMARY
A2: Tab 5: Final Ranked View — Value, Effort, Confidence, Phase Relevance
A4: RANKED OPPORTUNITY VIEW
A5: Opportunity | B5: Net Year 1 Benefit | C5: Effort | D5: Confidence | E5: Phase Recommendation
A6: AO-02: Automated Callback Triggering | B6: ='3. Opportunities'!H7 -> 4047746.4 | C6: Low (GBP45k) | D6: High | E6: Phase 1 — self-contained, no integration required
A7: AO-06: Automated Follow-Up Reminders | B7: ='3. Opportunities'!H11 -> 3119404.1 | C7: Low (GBP45k) | D7: Low | E7: Phase 1b — requires compliance sign-off
A8: AO-04: Customer Balance & Account View | B8: ='3. Opportunities'!H9 -> 3054178 | C8: Low (GBP45k) | D8: Medium | E8: Phase 1 — foundational portal function
A9: AO-01: Promise-to-Pay Self-Service | B9: ='3. Opportunities'!H6 -> 1588816 | C9: Low (GBP45k) | D9: Medium | E9: Phase 1 — primary anchor journey
A10: AO-03: Real-Time Status Synchronisation | B10: ='3. Opportunities'!H8 -> 1331922.1 | C10: Mid (GBP85k) | D10: High | E10: Pre-Phase 1 — enables all other opportunities
A11: AO-05: Risk-Based Queue Prioritisation | B11: ='3. Opportunities'!H10 -> 995582 | C11: Mid (GBP85k) | D11: Low | E11: Phase 2 — requires clean status foundation first
A13: PHASE 1 COMBINED CASE
A14: Component | B14: Base | C14: Conservative | D14: Floor | E14: Notes
A15: Hard savings — AO-01, AO-02, AO-03, AO-04 | B15: ='4. Calculations'!B21 -> 168984.93 | C15: ='4. Calculations'!C21 -> 168984.93 | D15: ='4. Calculations'!D21 -> 168984.93 | E15: High confidence — defensible with operational data
A16: Revenue uplift — combined (base/cons/floor) | B16: ='4. Calculations'!B22 -> 6240000 | C16: ='4. Calculations'!C22 -> 3120000 | D16: ='4. Calculations'!D22 -> 1440000 | E16: LOW CONFIDENCE — present separately from hard savings
A17: Total annual benefit | B17: ='4. Calculations'!B23 -> 6408984.9 | C17: ='4. Calculations'!C23 -> 3288984.9 | D17: ='4. Calculations'!D23 -> 1608984.9
A18: Implementation cost (mid-complexity) | B18: ='4. Calculations'!B24 -> -85000 | C18: ='4. Calculations'!C24 -> -85000 | D18: ='4. Calculations'!D24 -> -85000 | E18: GBP85k — less than 9 days of base uplift
A19: Net Year 1 benefit | B19: ='4. Calculations'!B25 -> 6323984.9 | C19: ='4. Calculations'!C25 -> 3203984.9 | D19: ='4. Calculations'!D25 -> 1523984.9 | E19: Positive in all three scenarios
A20: 12-month ROI | B20: ='4. Calculations'!B27 -> 74.399823 | C20: ='4. Calculations'!C27 -> 37.69394 | D20: ='4. Calculations'!D27 -> 17.929235
A21: Payback period (months) | B21: ='4. Calculations'!B26 -> 0.15915157 | C21: ='4. Calculations'!C26 -> 0.31012608 | D21: ='4. Calculations'!D26 -> 0.63394006
A23: PHASE 1 MEASUREMENT FRAMEWORK
A24: Daniel Okoye confirmed: Phase 1 must include measurement infrastructure to validate attribution post-launch.
A25: Metric | B25: Baseline (pre-launch) | C25: Target (90 days) | D25: Owner | E25: Links to
A26: Promise-to-Pay portal submission rate | B26: 0% (no portal) | C26: 0.191 | D26: Priya Nair | E26: AO-01, JTBD-04
A27: Awaiting Follow-Up backlog count | B27: 643 accounts | C27: < 300 accounts | D27: Amina Rahman | E27: AO-02, PP-02
A28: Duplicate activity rate | B28: 20.4% | C28: < 5% | D28: Amina Rahman | E28: AO-03, PP-01
A29: Agent admin time as % of total | B29: 34.2% (sample) | C29: < 20% | D29: Amina Rahman | E29: AO-03, PP-03
A30: Missed follow-up rate | B30: 14% | C30: < 8% | D30: Daniel Okoye | E30: AO-02, PP-02
A31: Portal adoption rate (eligible accounts) | B31: 0% | C31: 0.65 | D31: Priya Nair | E31: JTBD-01, AO-01
